<?xml version="1.0" encoding="utf-8"?>
<!-- =================================================================================== -->
<!-- |    This document was autogenerated by xacro from robot.urdf.xacro               | -->
<!-- |    EDITING THIS FILE BY HAND IS NOT RECOMMENDED                                 | -->
<!-- =================================================================================== -->
<robot name="aescape_robot">
  <joint name="right_arm_base_link_calibration" type="fixed">
    <parent link="left_arm_base_link"/>
    <child link="right_arm_base_link"/>
    <origin rpy="0 0 3.14159265359" xyz="1.0176 0.0111 -0.0046"/>
    <!-- Default Values -->
  </joint>
  <link name="right_arm_base_link"/>
  <joint name="right_arm_joint_right_arm_base_link" type="fixed">
    <parent link="right_arm_base_link"/>
    <child link="right_arm_link0"/>
    <origin rpy="0 0 0" xyz="0 0 0"/>
  </joint>
  <!--xacro:property name="joint_damping" value="1.0"/>
    <xacro:unless value="${in_gazebo == 'false'}">
      <link name="world" />
      <joint name="robot_to_world" type="fixed">
        <parent link="world" />
        <child link="${arm_id}_link0" />
        <origin rpy="${rpy}" xyz="${xyz}"/>
        <dynamics damping="${joint_damping}"/>
      </joint>
      
    </xacro:unless-->
  <link name="right_arm_link0">
    <visual>
      <geometry>
        <mesh filename="package://aescape_gazebo/meshes/visual/link0.dae"/>
      </geometry>
    </visual>
    <collision>
      <geometry>
        <mesh filename="package://aescape_gazebo/meshes/collision/link0.stl"/>
      </geometry>
    </collision>
    <inertial>
      <origin rpy="0 0 0" xyz="0 0 0"/>
      <mass value="3.06"/>
      <inertia ixx="0.3" ixy="0.0" ixz="0.0" iyy="0.3" iyz="0.0" izz="0.3"/>
    </inertial>
  </link>
  <link name="right_arm_link1">
    <visual>
      <geometry>
        <mesh filename="package://aescape_gazebo/meshes/visual/link1.dae"/>
      </geometry>
    </visual>
    <collision>
      <geometry>
        <mesh filename="package://aescape_gazebo/meshes/collision/link1.stl"/>
      </geometry>
    </collision>
    <inertial>
      <origin rpy="0 0 0" xyz="3.875e-03 2.081e-03 -0.1750"/>
      <mass value="4.970684"/>
      <inertia ixx="7.0337e-01" ixy="-1.3900e-04" ixz="6.7720e-03" iyy="7.0661e-01" iyz="1.9169e-02" izz="9.1170e-03"/>
    </inertial>
  </link>
  <joint name="right_arm_joint1" type="revolute">
    <safety_controller k_position="100.0" k_velocity="40.0" soft_lower_limit="-2.8973" soft_upper_limit="2.8973"/>
    <origin rpy="0 0 0" xyz="0 0 0.333"/>
    <parent link="right_arm_link0"/>
    <child link="right_arm_link1"/>
    <axis xyz="0 0 1"/>
    <limit effort="87" lower="-2.8973" upper="2.8973" velocity="2.1750"/>
    <dynamics damping="10.0" friction="5.0"/>
  </joint>
  <link name="right_arm_link2">
    <visual>
      <geometry>
        <mesh filename="package://aescape_gazebo/meshes/visual/link2.dae"/>
      </geometry>
    </visual>
    <collision>
      <geometry>
        <mesh filename="package://aescape_gazebo/meshes/collision/link2.stl"/>
      </geometry>
    </collision>
    <inertial>
      <origin rpy="0 0 0" xyz="-3.141e-03 -2.872e-02 3.495e-03"/>
      <mass value="0.646926"/>
      <inertia ixx="7.9620e-03" ixy="-3.9250e-03" ixz="1.0254e-02" iyy="2.8110e-02" iyz="7.0400e-04" izz="2.5995e-02"/>
    </inertial>
  </link>
  <joint name="right_arm_joint2" type="revolute">
    <safety_controller k_position="100.0" k_velocity="40.0" soft_lower_limit="-1.7628" soft_upper_limit="1.7628"/>
    <origin rpy="-1.57079632679 0 0" xyz="0 0 0"/>
    <parent link="right_arm_link1"/>
    <child link="right_arm_link2"/>
    <axis xyz="0 0 1"/>
    <limit effort="87" lower="-1.7628" upper="1.7628" velocity="2.1750"/>
    <dynamics damping="5.0" friction="2.0"/>
  </joint>
  <link name="right_arm_link3">
    <visual>
      <geometry>
        <mesh filename="package://aescape_gazebo/meshes/visual/link3.dae"/>
      </geometry>
    </visual>
    <collision>
      <geometry>
        <mesh filename="package://aescape_gazebo/meshes/collision/link3.stl"/>
      </geometry>
    </collision>
    <inertial>
      <origin rpy="0 0 0" xyz="2.7518e-02 3.9252e-02 -6.6502e-02"/>
      <mass value="3.228604"/>
      <inertia ixx="3.7242e-02" ixy="-4.7610e-03" ixz="-1.1396e-02" iyy="3.6155e-02" iyz="-1.2805e-02" izz="1.0830e-02"/>
    </inertial>
  </link>
  <joint name="right_arm_joint3" type="revolute">
    <safety_controller k_position="100.0" k_velocity="40.0" soft_lower_limit="-2.8973" soft_upper_limit="2.8973"/>
    <origin rpy="1.57079632679 0 0" xyz="0 -0.316 0"/>
    <parent link="right_arm_link2"/>
    <child link="right_arm_link3"/>
    <axis xyz="0 0 1"/>
    <limit effort="87" lower="-2.8973" upper="2.8973" velocity="2.1750"/>
    <dynamics damping="5.0" friction="2.0"/>
  </joint>
  <link name="right_arm_link4">
    <visual>
      <geometry>
        <mesh filename="package://aescape_gazebo/meshes/visual/link4.dae"/>
      </geometry>
    </visual>
    <collision>
      <geometry>
        <mesh filename="package://aescape_gazebo/meshes/collision/link4.stl"/>
      </geometry>
    </collision>
    <inertial>
      <origin rpy="0 0 0" xyz="-5.317e-02 1.04419e-01 2.7454e-02"/>
      <mass value="3.587895"/>
      <inertia ixx="2.5853e-02" ixy="7.7960e-03" ixz="-1.3320e-03" iyy="1.9552e-02" iyz="8.6410e-03" izz="2.8323e-02"/>
    </inertial>
  </link>
  <joint name="right_arm_joint4" type="revolute">
    <safety_controller k_position="100.0" k_velocity="40.0" soft_lower_limit="-3.0718" soft_upper_limit="-0.0698"/>
    <origin rpy="1.57079632679 0 0" xyz="0.0825 0 0"/>
    <parent link="right_arm_link3"/>
    <child link="right_arm_link4"/>
    <axis xyz="0 0 1"/>
    <limit effort="87" lower="-3.0718" upper="-0.0698" velocity="2.1750"/>
    <dynamics damping="1.0" friction="0.5"/>
  </joint>
  <link name="right_arm_link5">
    <visual>
      <geometry>
        <mesh filename="package://aescape_gazebo/meshes/visual/link5.dae"/>
      </geometry>
    </visual>
    <collision>
      <geometry>
        <mesh filename="package://aescape_gazebo/meshes/collision/link5.stl"/>
      </geometry>
    </collision>
    <inertial>
      <origin rpy="0 0 0" xyz="-1.1953e-02 4.1065e-02 -3.8437e-02"/>
      <mass value="1.225946"/>
      <inertia ixx="3.5549e-02" ixy="-2.1170e-03" ixz="-4.0370e-03" iyy="2.9474e-02" iyz="2.2900e-04" izz="8.6270e-03"/>
    </inertial>
  </link>
  <joint name="right_arm_joint5" type="revolute">
    <safety_controller k_position="100.0" k_velocity="40.0" soft_lower_limit="-2.8973" soft_upper_limit="2.8973"/>
    <origin rpy="-1.57079632679 0 0" xyz="-0.0825 0.384 0"/>
    <parent link="right_arm_link4"/>
    <child link="right_arm_link5"/>
    <axis xyz="0 0 1"/>
    <limit effort="12" lower="-2.8973" upper="2.8973" velocity="2.6100"/>
    <dynamics damping="2.0" friction="1.0"/>
  </joint>
  <link name="right_arm_link6">
    <visual>
      <geometry>
        <mesh filename="package://aescape_gazebo/meshes/visual/link6.dae"/>
      </geometry>
    </visual>
    <collision>
      <geometry>
        <mesh filename="package://aescape_gazebo/meshes/collision/link6.stl"/>
      </geometry>
    </collision>
    <inertial>
      <origin rpy="0 0 0" xyz="6.0149e-02 -1.4117e-02 -1.0517e-02"/>
      <mass value="1.666555"/>
      <inertia ixx="1.9640e-03" ixy="1.0900e-04" ixz="-1.1580e-03" iyy="4.3540e-03" iyz="3.4100e-04" izz="5.4330e-03"/>
    </inertial>
  </link>
  <joint name="right_arm_joint6" type="revolute">
    <safety_controller k_position="100.0" k_velocity="40.0" soft_lower_limit="-0.0175" soft_upper_limit="3.7525"/>
    <origin rpy="1.57079632679 0 0" xyz="0 0 0"/>
    <parent link="right_arm_link5"/>
    <child link="right_arm_link6"/>
    <axis xyz="0 0 1"/>
    <limit effort="12" lower="-0.0175" upper="3.7525" velocity="2.6100"/>
    <dynamics damping="1.0" friction="0.5"/>
  </joint>
  <link name="right_arm_link7">
    <visual>
      <geometry>
        <mesh filename="package://aescape_gazebo/meshes/visual/link7.dae"/>
      </geometry>
    </visual>
    <collision>
      <geometry>
        <mesh filename="package://aescape_gazebo/meshes/collision/link7.stl"/>
      </geometry>
    </collision>
    <inertial>
      <origin rpy="0 0 0" xyz="1.0517e-02 -4.252e-03 6.1597e-02"/>
      <mass value="7.35522e-01"/>
      <inertia ixx="1.2516e-02" ixy="-4.2800e-04" ixz="-1.1960e-03" iyy="1.0027e-02" iyz="-7.4100e-04" izz="4.8150e-03"/>
    </inertial>
  </link>
  <joint name="right_arm_joint7" type="revolute">
    <safety_controller k_position="100.0" k_velocity="40.0" soft_lower_limit="-2.8973" soft_upper_limit="2.8973"/>
    <origin rpy="1.57079632679 0 0" xyz="0.088 -0.106 0.0"/>
    <parent link="right_arm_link6"/>
    <child link="right_arm_link7"/>
    <axis xyz="0 0 1"/>
    <limit effort="12" lower="-2.8973" upper="2.8973" velocity="2.6100"/>
    <dynamics damping="1.0" friction="0.5"/>
  </joint>
  <!--link name="${arm_id}_link8">      
      <visual>
        <geometry>
          <mesh filename="package://${description_pkg}/meshes/visual/tool.dae" scale="0.019 0.019 0.019"/>>
        </geometry>
      </visual>
      <collision>
        <geometry>
          <mesh filename="package://${description_pkg}/meshes/collision/tool.stl" scale="0.019 0.019 0.019"/>
        </geometry>
      </collision>
      <inertial>
        <origin xyz="0 0 0" rpy="0 0 0"/>
        <mass value="0.0"/>
        <inertia ixx="0.001" ixy="0.0" ixz="0.0" iyy="0.001" iyz="0.0" izz="0.001"/>
      </inertial>
    </link>
    <joint name="${arm_id}_joint8" type="fixed">
      <origin rpy="${pi/2} 0 0" xyz="-0.02 0.0 0.046"/>
      <parent link="${arm_id}_link7"/>
      <child link="${arm_id}_link8"/>
      <axis xyz="0 0 1"/>
    </joint-->
  <link name="right_arm_link8">
    <inertial>
      <origin rpy="0 0 0" xyz="0 0 0"/>
      <mass value="0.0"/>
      <inertia ixx="0.001" ixy="0.0" ixz="0.0" iyy="0.001" iyz="0.0" izz="0.001"/>
    </inertial>
  </link>
  <joint name="right_arm_joint8" type="fixed">
    <origin rpy="0 0 0" xyz="0 0 0"/>
    <parent link="right_arm_link7"/>
    <child link="right_arm_link8"/>
    <axis xyz="0 0 0"/>
  </joint>
  <link name="left_arm_base_link"/>
  <joint name="left_arm_joint_left_arm_base_link" type="fixed">
    <parent link="left_arm_base_link"/>
    <child link="left_arm_link0"/>
    <origin rpy="0 0 0" xyz="0 0 0"/>
  </joint>
  <!--xacro:property name="joint_damping" value="1.0"/>
    <xacro:unless value="${in_gazebo == 'false'}">
      <link name="world" />
      <joint name="robot_to_world" type="fixed">
        <parent link="world" />
        <child link="${arm_id}_link0" />
        <origin rpy="${rpy}" xyz="${xyz}"/>
        <dynamics damping="${joint_damping}"/>
      </joint>
      
    </xacro:unless-->
  <link name="left_arm_link0">
    <visual>
      <geometry>
        <mesh filename="package://aescape_gazebo/meshes/visual/link0.dae"/>
      </geometry>
    </visual>
    <collision>
      <geometry>
        <mesh filename="package://aescape_gazebo/meshes/collision/link0.stl"/>
      </geometry>
    </collision>
    <inertial>
      <origin rpy="0 0 0" xyz="0 0 0"/>
      <mass value="3.06"/>
      <inertia ixx="0.3" ixy="0.0" ixz="0.0" iyy="0.3" iyz="0.0" izz="0.3"/>
    </inertial>
  </link>
  <link name="left_arm_link1">
    <visual>
      <geometry>
        <mesh filename="package://aescape_gazebo/meshes/visual/link1.dae"/>
      </geometry>
    </visual>
    <collision>
      <geometry>
        <mesh filename="package://aescape_gazebo/meshes/collision/link1.stl"/>
      </geometry>
    </collision>
    <inertial>
      <origin rpy="0 0 0" xyz="3.875e-03 2.081e-03 -0.1750"/>
      <mass value="4.970684"/>
      <inertia ixx="7.0337e-01" ixy="-1.3900e-04" ixz="6.7720e-03" iyy="7.0661e-01" iyz="1.9169e-02" izz="9.1170e-03"/>
    </inertial>
  </link>
  <joint name="left_arm_joint1" type="revolute">
    <safety_controller k_position="100.0" k_velocity="40.0" soft_lower_limit="-2.8973" soft_upper_limit="2.8973"/>
    <origin rpy="0 0 0" xyz="0 0 0.333"/>
    <parent link="left_arm_link0"/>
    <child link="left_arm_link1"/>
    <axis xyz="0 0 1"/>
    <limit effort="87" lower="-2.8973" upper="2.8973" velocity="2.1750"/>
    <dynamics damping="10.0" friction="5.0"/>
  </joint>
  <link name="left_arm_link2">
    <visual>
      <geometry>
        <mesh filename="package://aescape_gazebo/meshes/visual/link2.dae"/>
      </geometry>
    </visual>
    <collision>
      <geometry>
        <mesh filename="package://aescape_gazebo/meshes/collision/link2.stl"/>
      </geometry>
    </collision>
    <inertial>
      <origin rpy="0 0 0" xyz="-3.141e-03 -2.872e-02 3.495e-03"/>
      <mass value="0.646926"/>
      <inertia ixx="7.9620e-03" ixy="-3.9250e-03" ixz="1.0254e-02" iyy="2.8110e-02" iyz="7.0400e-04" izz="2.5995e-02"/>
    </inertial>
  </link>
  <joint name="left_arm_joint2" type="revolute">
    <safety_controller k_position="100.0" k_velocity="40.0" soft_lower_limit="-1.7628" soft_upper_limit="1.7628"/>
    <origin rpy="-1.57079632679 0 0" xyz="0 0 0"/>
    <parent link="left_arm_link1"/>
    <child link="left_arm_link2"/>
    <axis xyz="0 0 1"/>
    <limit effort="87" lower="-1.7628" upper="1.7628" velocity="2.1750"/>
    <dynamics damping="5.0" friction="2.0"/>
  </joint>
  <link name="left_arm_link3">
    <visual>
      <geometry>
        <mesh filename="package://aescape_gazebo/meshes/visual/link3.dae"/>
      </geometry>
    </visual>
    <collision>
      <geometry>
        <mesh filename="package://aescape_gazebo/meshes/collision/link3.stl"/>
      </geometry>
    </collision>
    <inertial>
      <origin rpy="0 0 0" xyz="2.7518e-02 3.9252e-02 -6.6502e-02"/>
      <mass value="3.228604"/>
      <inertia ixx="3.7242e-02" ixy="-4.7610e-03" ixz="-1.1396e-02" iyy="3.6155e-02" iyz="-1.2805e-02" izz="1.0830e-02"/>
    </inertial>
  </link>
  <joint name="left_arm_joint3" type="revolute">
    <safety_controller k_position="100.0" k_velocity="40.0" soft_lower_limit="-2.8973" soft_upper_limit="2.8973"/>
    <origin rpy="1.57079632679 0 0" xyz="0 -0.316 0"/>
    <parent link="left_arm_link2"/>
    <child link="left_arm_link3"/>
    <axis xyz="0 0 1"/>
    <limit effort="87" lower="-2.8973" upper="2.8973" velocity="2.1750"/>
    <dynamics damping="5.0" friction="2.0"/>
  </joint>
  <link name="left_arm_link4">
    <visual>
      <geometry>
        <mesh filename="package://aescape_gazebo/meshes/visual/link4.dae"/>
      </geometry>
    </visual>
    <collision>
      <geometry>
        <mesh filename="package://aescape_gazebo/meshes/collision/link4.stl"/>
      </geometry>
    </collision>
    <inertial>
      <origin rpy="0 0 0" xyz="-5.317e-02 1.04419e-01 2.7454e-02"/>
      <mass value="3.587895"/>
      <inertia ixx="2.5853e-02" ixy="7.7960e-03" ixz="-1.3320e-03" iyy="1.9552e-02" iyz="8.6410e-03" izz="2.8323e-02"/>
    </inertial>
  </link>
  <joint name="left_arm_joint4" type="revolute">
    <safety_controller k_position="100.0" k_velocity="40.0" soft_lower_limit="-3.0718" soft_upper_limit="-0.0698"/>
    <origin rpy="1.57079632679 0 0" xyz="0.0825 0 0"/>
    <parent link="left_arm_link3"/>
    <child link="left_arm_link4"/>
    <axis xyz="0 0 1"/>
    <limit effort="87" lower="-3.0718" upper="-0.0698" velocity="2.1750"/>
    <dynamics damping="1.0" friction="0.5"/>
  </joint>
  <link name="left_arm_link5">
    <visual>
      <geometry>
        <mesh filename="package://aescape_gazebo/meshes/visual/link5.dae"/>
      </geometry>
    </visual>
    <collision>
      <geometry>
        <mesh filename="package://aescape_gazebo/meshes/collision/link5.stl"/>
      </geometry>
    </collision>
    <inertial>
      <origin rpy="0 0 0" xyz="-1.1953e-02 4.1065e-02 -3.8437e-02"/>
      <mass value="1.225946"/>
      <inertia ixx="3.5549e-02" ixy="-2.1170e-03" ixz="-4.0370e-03" iyy="2.9474e-02" iyz="2.2900e-04" izz="8.6270e-03"/>
    </inertial>
  </link>
  <joint name="left_arm_joint5" type="revolute">
    <safety_controller k_position="100.0" k_velocity="40.0" soft_lower_limit="-2.8973" soft_upper_limit="2.8973"/>
    <origin rpy="-1.57079632679 0 0" xyz="-0.0825 0.384 0"/>
    <parent link="left_arm_link4"/>
    <child link="left_arm_link5"/>
    <axis xyz="0 0 1"/>
    <limit effort="12" lower="-2.8973" upper="2.8973" velocity="2.6100"/>
    <dynamics damping="2.0" friction="1.0"/>
  </joint>
  <link name="left_arm_link6">
    <visual>
      <geometry>
        <mesh filename="package://aescape_gazebo/meshes/visual/link6.dae"/>
      </geometry>
    </visual>
    <collision>
      <geometry>
        <mesh filename="package://aescape_gazebo/meshes/collision/link6.stl"/>
      </geometry>
    </collision>
    <inertial>
      <origin rpy="0 0 0" xyz="6.0149e-02 -1.4117e-02 -1.0517e-02"/>
      <mass value="1.666555"/>
      <inertia ixx="1.9640e-03" ixy="1.0900e-04" ixz="-1.1580e-03" iyy="4.3540e-03" iyz="3.4100e-04" izz="5.4330e-03"/>
    </inertial>
  </link>
  <joint name="left_arm_joint6" type="revolute">
    <safety_controller k_position="100.0" k_velocity="40.0" soft_lower_limit="-0.0175" soft_upper_limit="3.7525"/>
    <origin rpy="1.57079632679 0 0" xyz="0 0 0"/>
    <parent link="left_arm_link5"/>
    <child link="left_arm_link6"/>
    <axis xyz="0 0 1"/>
    <limit effort="12" lower="-0.0175" upper="3.7525" velocity="2.6100"/>
    <dynamics damping="1.0" friction="0.5"/>
  </joint>
  <link name="left_arm_link7">
    <visual>
      <geometry>
        <mesh filename="package://aescape_gazebo/meshes/visual/link7.dae"/>
      </geometry>
    </visual>
    <collision>
      <geometry>
        <mesh filename="package://aescape_gazebo/meshes/collision/link7.stl"/>
      </geometry>
    </collision>
    <inertial>
      <origin rpy="0 0 0" xyz="1.0517e-02 -4.252e-03 6.1597e-02"/>
      <mass value="7.35522e-01"/>
      <inertia ixx="1.2516e-02" ixy="-4.2800e-04" ixz="-1.1960e-03" iyy="1.0027e-02" iyz="-7.4100e-04" izz="4.8150e-03"/>
    </inertial>
  </link>
  <joint name="left_arm_joint7" type="revolute">
    <safety_controller k_position="100.0" k_velocity="40.0" soft_lower_limit="-2.8973" soft_upper_limit="2.8973"/>
    <origin rpy="1.57079632679 0 0" xyz="0.088 -0.106 0.0"/>
    <parent link="left_arm_link6"/>
    <child link="left_arm_link7"/>
    <axis xyz="0 0 1"/>
    <limit effort="12" lower="-2.8973" upper="2.8973" velocity="2.6100"/>
    <dynamics damping="1.0" friction="0.5"/>
  </joint>
  <!--link name="${arm_id}_link8">      
      <visual>
        <geometry>
          <mesh filename="package://${description_pkg}/meshes/visual/tool.dae" scale="0.019 0.019 0.019"/>>
        </geometry>
      </visual>
      <collision>
        <geometry>
          <mesh filename="package://${description_pkg}/meshes/collision/tool.stl" scale="0.019 0.019 0.019"/>
        </geometry>
      </collision>
      <inertial>
        <origin xyz="0 0 0" rpy="0 0 0"/>
        <mass value="0.0"/>
        <inertia ixx="0.001" ixy="0.0" ixz="0.0" iyy="0.001" iyz="0.0" izz="0.001"/>
      </inertial>
    </link>
    <joint name="${arm_id}_joint8" type="fixed">
      <origin rpy="${pi/2} 0 0" xyz="-0.02 0.0 0.046"/>
      <parent link="${arm_id}_link7"/>
      <child link="${arm_id}_link8"/>
      <axis xyz="0 0 1"/>
    </joint-->
  <link name="left_arm_link8">
    <inertial>
      <origin rpy="0 0 0" xyz="0 0 0"/>
      <mass value="0.0"/>
      <inertia ixx="0.001" ixy="0.0" ixz="0.0" iyy="0.001" iyz="0.0" izz="0.001"/>
    </inertial>
  </link>
  <joint name="left_arm_joint8" type="fixed">
    <origin rpy="0 0 0" xyz="0 0 0"/>
    <parent link="left_arm_link7"/>
    <child link="left_arm_link8"/>
    <axis xyz="0 0 0"/>
  </joint>
  <link name="left_arm_tool_link">
    <visual>
      <geometry>
        <mesh filename="package://aescape_gazebo/meshes/visual/left_tp.dae"/>
      </geometry>
    </visual>
    <collision>
      <geometry>
        <mesh filename="package://aescape_gazebo/meshes/collision/left_tp.stl"/>
      </geometry>
    </collision>
    <inertial>
      <origin rpy="0 0 0" xyz="0 0 0"/>
      <mass value="0.68"/>
      <inertia ixx="0.1" ixy="0.0" ixz="0.0" iyy="0.1" iyz="0.0" izz="0.1"/>
    </inertial>
  </link>
  <joint name="left_arm_joint_tool" type="fixed">
    <parent link="left_arm_link8"/>
    <child link="left_arm_tool_link"/>
    <origin rpy="0 0 0" xyz="0.0 0.0 0.0"/>
  </joint>
  <gazebo reference="left_arm_tool_link">
    <material>Gazebo/Grey</material>
    <mu1>0.2</mu1>
    <mu2>0.2</mu2>
    <sensor name="left_arm_tool_bumper" type="contact">
      <always_on>true</always_on>
      <contact>
        <collision>left_arm_link7_fixed_joint_lump__left_arm_tool_link_collision_1</collision>
      </contact>
      <plugin filename="libgazebo_ros_bumper.so" name="left_arm_tool_plugin">
        <bumperTopicName>/left/left_arm_tool_link/bumper</bumperTopicName>
        <frameName>left_arm_tool_link</frameName>
      </plugin>
    </sensor>
  </gazebo>
  <link name="right_arm_tool_link">
    <visual>
      <geometry>
        <mesh filename="package://aescape_gazebo/meshes/visual/left_tp.dae"/>
      </geometry>
    </visual>
    <collision>
      <geometry>
        <mesh filename="package://aescape_gazebo/meshes/collision/left_tp.stl"/>
      </geometry>
    </collision>
    <inertial>
      <origin rpy="0 0 0" xyz="0 0 0"/>
      <mass value="0.68"/>
      <inertia ixx="0.1" ixy="0.0" ixz="0.0" iyy="0.1" iyz="0.0" izz="0.1"/>
    </inertial>
  </link>
  <joint name="right_arm_joint_tool" type="fixed">
    <parent link="right_arm_link8"/>
    <child link="right_arm_tool_link"/>
    <origin rpy="0 0 0" xyz="0.0 0.0 0.0"/>
  </joint>
  <gazebo reference="right_arm_tool_link">
    <material>Gazebo/Grey</material>
    <mu1>0.2</mu1>
    <mu2>0.2</mu2>
    <sensor name="right_arm_tool_bumper" type="contact">
      <always_on>true</always_on>
      <contact>
        <collision>right_arm_link7_fixed_joint_lump__right_arm_tool_link_collision_1</collision>
      </contact>
      <plugin filename="libgazebo_ros_bumper.so" name="right_arm_tool_plugin">
        <bumperTopicName>/right/right_arm_tool_link/bumper</bumperTopicName>
        <frameName>right_arm_tool_link</frameName>
      </plugin>
    </sensor>
  </gazebo>
  <gazebo reference="left_arm_link0">
    <material>Gazebo/Grey</material>
    <mu1>0.2</mu1>
    <mu2>0.2</mu2>
  </gazebo>
  <!-- Link1 -->
  <gazebo reference="left_arm_link1">
    <material>Gazebo/White</material>
    <mu1>0.2</mu1>
    <mu2>0.2</mu2>
  </gazebo>
  <!-- Link2 -->
  <gazebo reference="left_arm_link2">
    <material>Gazebo/White</material>
    <mu1>0.2</mu1>
    <mu2>0.2</mu2>
  </gazebo>
  <!-- Link3 -->
  <gazebo reference="left_arm_link3">
    <material>Gazebo/White</material>
    <mu1>0.2</mu1>
    <mu2>0.2</mu2>
  </gazebo>
  <!-- Link4 -->
  <gazebo reference="left_arm_link4">
    <material>Gazebo/White</material>
    <mu1>0.2</mu1>
    <mu2>0.2</mu2>
  </gazebo>
  <!-- Link5 -->
  <gazebo reference="left_arm_link5">
    <material>Gazebo/White</material>
    <mu1>0.2</mu1>
    <mu2>0.2</mu2>
  </gazebo>
  <!-- Link6 -->
  <gazebo reference="left_arm_link6">
    <material>Gazebo/White</material>
    <mu1>0.2</mu1>
    <mu2>0.2</mu2>
  </gazebo>
  <!-- Link7 -->
  <gazebo reference="left_arm_link7">
    <material>Gazebo/Grey</material>
    <mu1>0.2</mu1>
    <mu2>0.2</mu2>
  </gazebo>
  <!-- Link8 -->
  <gazebo reference="left_arm_link8">
    <material>Gazebo/Grey</material>
    <mu1>0.2</mu1>
    <mu2>0.2</mu2>
  </gazebo>
  <!-- Joint1 -->
  <gazebo reference="left_arm_joint1">
    <implicitSpringDamper>1</implicitSpringDamper>
    <provideFeedback>true</provideFeedback>
  </gazebo>
  <!-- Joint2 -->
  <gazebo reference="left_arm_joint2">
    <implicitSpringDamper>1</implicitSpringDamper>
    <provideFeedback>true</provideFeedback>
  </gazebo>
  <!-- Joint3 -->
  <gazebo reference="left_arm_joint3">
    <implicitSpringDamper>1</implicitSpringDamper>
    <provideFeedback>true</provideFeedback>
  </gazebo>
  <!-- Joint4 -->
  <gazebo reference="left_arm_joint4">
    <implicitSpringDamper>1</implicitSpringDamper>
    <provideFeedback>true</provideFeedback>
  </gazebo>
  <!-- Joint5 -->
  <gazebo reference="left_arm_joint5">
    <implicitSpringDamper>1</implicitSpringDamper>
    <provideFeedback>true</provideFeedback>
  </gazebo>
  <!-- Joint5 -->
  <gazebo reference="left_arm_joint6">
    <implicitSpringDamper>1</implicitSpringDamper>
    <provideFeedback>true</provideFeedback>
  </gazebo>
  <!-- Joint6 -->
  <gazebo reference="left_arm_joint7">
    <implicitSpringDamper>1</implicitSpringDamper>
    <provideFeedback>true</provideFeedback>
  </gazebo>
  <!-- Joint7 -->
  <gazebo reference="left_arm_joint8">
    <implicitSpringDamper>1</implicitSpringDamper>
    <provideFeedback>true</provideFeedback>
  </gazebo>
  <gazebo reference="right_arm_link0">
    <material>Gazebo/Grey</material>
    <mu1>0.2</mu1>
    <mu2>0.2</mu2>
  </gazebo>
  <!-- Link1 -->
  <gazebo reference="right_arm_link1">
    <material>Gazebo/White</material>
    <mu1>0.2</mu1>
    <mu2>0.2</mu2>
  </gazebo>
  <!-- Link2 -->
  <gazebo reference="right_arm_link2">
    <material>Gazebo/White</material>
    <mu1>0.2</mu1>
    <mu2>0.2</mu2>
  </gazebo>
  <!-- Link3 -->
  <gazebo reference="right_arm_link3">
    <material>Gazebo/White</material>
    <mu1>0.2</mu1>
    <mu2>0.2</mu2>
  </gazebo>
  <!-- Link4 -->
  <gazebo reference="right_arm_link4">
    <material>Gazebo/White</material>
    <mu1>0.2</mu1>
    <mu2>0.2</mu2>
  </gazebo>
  <!-- Link5 -->
  <gazebo reference="right_arm_link5">
    <material>Gazebo/White</material>
    <mu1>0.2</mu1>
    <mu2>0.2</mu2>
  </gazebo>
  <!-- Link6 -->
  <gazebo reference="right_arm_link6">
    <material>Gazebo/White</material>
    <mu1>0.2</mu1>
    <mu2>0.2</mu2>
  </gazebo>
  <!-- Link7 -->
  <gazebo reference="right_arm_link7">
    <material>Gazebo/Grey</material>
    <mu1>0.2</mu1>
    <mu2>0.2</mu2>
  </gazebo>
  <!-- Link8 -->
  <gazebo reference="right_arm_link8">
    <material>Gazebo/Grey</material>
    <mu1>0.2</mu1>
    <mu2>0.2</mu2>
  </gazebo>
  <!-- Joint1 -->
  <gazebo reference="right_arm_joint1">
    <implicitSpringDamper>1</implicitSpringDamper>
    <provideFeedback>true</provideFeedback>
  </gazebo>
  <!-- Joint2 -->
  <gazebo reference="right_arm_joint2">
    <implicitSpringDamper>1</implicitSpringDamper>
    <provideFeedback>true</provideFeedback>
  </gazebo>
  <!-- Joint3 -->
  <gazebo reference="right_arm_joint3">
    <implicitSpringDamper>1</implicitSpringDamper>
    <provideFeedback>true</provideFeedback>
  </gazebo>
  <!-- Joint4 -->
  <gazebo reference="right_arm_joint4">
    <implicitSpringDamper>1</implicitSpringDamper>
    <provideFeedback>true</provideFeedback>
  </gazebo>
  <!-- Joint5 -->
  <gazebo reference="right_arm_joint5">
    <implicitSpringDamper>1</implicitSpringDamper>
    <provideFeedback>true</provideFeedback>
  </gazebo>
  <!-- Joint5 -->
  <gazebo reference="right_arm_joint6">
    <implicitSpringDamper>1</implicitSpringDamper>
    <provideFeedback>true</provideFeedback>
  </gazebo>
  <!-- Joint6 -->
  <gazebo reference="right_arm_joint7">
    <implicitSpringDamper>1</implicitSpringDamper>
    <provideFeedback>true</provideFeedback>
  </gazebo>
  <!-- Joint7 -->
  <gazebo reference="right_arm_joint8">
    <implicitSpringDamper>1</implicitSpringDamper>
    <provideFeedback>true</provideFeedback>
  </gazebo>
  <!-- Load ros control plugin -->
  <gazebo>
    <plugin filename="libgazebo_ros_control.so" name="gazebo_ros_control">
      <robotNamespace>/left</robotNamespace>
      <robotSimType>gazebo_ros_control/DefaultRobotHWSim</robotSimType>
      <legacyModeNS>true</legacyModeNS>
    </plugin>
  </gazebo>
  <!-- Load ft sensor plugin - joint7-->
  <gazebo>
    <plugin filename="libgazebo_ros_ft_sensor.so" name="ft_sensor">
      <robotNamespace>/left</robotNamespace>
      <updateRate>100.0</updateRate>
      <topicName>transformed_world</topicName>
      <jointName>left_arm_joint7</jointName>
    </plugin>
  </gazebo>
  <transmission name="left_arm_tran_1">
    <type>transmission_interface/SimpleTransmission</type>
    <joint name="left_arm_joint1">
      <hardwareInterface>hardware_interface/PositionJointInterface</hardwareInterface>
    </joint>
    <actuator name="left_arm_motor_1">
      <hardwareInterface>hardware_interface/PositionJointInterface</hardwareInterface>
      <mechanicalReduction>1</mechanicalReduction>
    </actuator>
  </transmission>
  <transmission name="left_arm_tran_2">
    <type>transmission_interface/SimpleTransmission</type>
    <joint name="left_arm_joint2">
      <hardwareInterface>hardware_interface/PositionJointInterface</hardwareInterface>
    </joint>
    <actuator name="left_arm_motor_2">
      <hardwareInterface>hardware_interface/PositionJointInterface</hardwareInterface>
      <mechanicalReduction>1</mechanicalReduction>
    </actuator>
  </transmission>
  <transmission name="left_arm_tran_3">
    <type>transmission_interface/SimpleTransmission</type>
    <joint name="left_arm_joint3">
      <hardwareInterface>hardware_interface/PositionJointInterface</hardwareInterface>
    </joint>
    <actuator name="left_arm_motor_3">
      <hardwareInterface>hardware_interface/PositionJointInterface</hardwareInterface>
      <mechanicalReduction>1</mechanicalReduction>
    </actuator>
  </transmission>
  <transmission name="left_arm_tran_4">
    <type>transmission_interface/SimpleTransmission</type>
    <joint name="left_arm_joint4">
      <hardwareInterface>hardware_interface/PositionJointInterface</hardwareInterface>
    </joint>
    <actuator name="left_arm_motor_4">
      <hardwareInterface>hardware_interface/PositionJointInterface</hardwareInterface>
      <mechanicalReduction>1</mechanicalReduction>
    </actuator>
  </transmission>
  <transmission name="left_arm_tran_5">
    <type>transmission_interface/SimpleTransmission</type>
    <joint name="left_arm_joint5">
      <hardwareInterface>hardware_interface/PositionJointInterface</hardwareInterface>
    </joint>
    <actuator name="left_arm_motor_5">
      <hardwareInterface>hardware_interface/PositionJointInterface</hardwareInterface>
      <mechanicalReduction>1</mechanicalReduction>
    </actuator>
  </transmission>
  <transmission name="left_arm_tran_6">
    <type>transmission_interface/SimpleTransmission</type>
    <joint name="left_arm_joint6">
      <hardwareInterface>hardware_interface/PositionJointInterface</hardwareInterface>
    </joint>
    <actuator name="left_arm_motor_6">
      <hardwareInterface>hardware_interface/PositionJointInterface</hardwareInterface>
      <mechanicalReduction>1</mechanicalReduction>
    </actuator>
  </transmission>
  <transmission name="left_arm_tran_7">
    <type>transmission_interface/SimpleTransmission</type>
    <joint name="left_arm_joint7">
      <hardwareInterface>hardware_interface/PositionJointInterface</hardwareInterface>
    </joint>
    <actuator name="left_arm_motor_7">
      <hardwareInterface>hardware_interface/PositionJointInterface</hardwareInterface>
      <mechanicalReduction>1</mechanicalReduction>
    </actuator>
  </transmission>
  <!-- Load ros control plugin -->
  <gazebo>
    <plugin filename="libgazebo_ros_control.so" name="gazebo_ros_control">
      <robotNamespace>/right</robotNamespace>
      <robotSimType>gazebo_ros_control/DefaultRobotHWSim</robotSimType>
      <legacyModeNS>true</legacyModeNS>
    </plugin>
  </gazebo>
  <!-- Load ft sensor plugin - joint7-->
  <gazebo>
    <plugin filename="libgazebo_ros_ft_sensor.so" name="ft_sensor">
      <robotNamespace>/right</robotNamespace>
      <updateRate>100.0</updateRate>
      <topicName>transformed_world</topicName>
      <jointName>right_arm_joint7</jointName>
    </plugin>
  </gazebo>
  <transmission name="right_arm_tran_1">
    <type>transmission_interface/SimpleTransmission</type>
    <joint name="right_arm_joint1">
      <hardwareInterface>hardware_interface/PositionJointInterface</hardwareInterface>
    </joint>
    <actuator name="right_arm_motor_1">
      <hardwareInterface>hardware_interface/PositionJointInterface</hardwareInterface>
      <mechanicalReduction>1</mechanicalReduction>
    </actuator>
  </transmission>
  <transmission name="right_arm_tran_2">
    <type>transmission_interface/SimpleTransmission</type>
    <joint name="right_arm_joint2">
      <hardwareInterface>hardware_interface/PositionJointInterface</hardwareInterface>
    </joint>
    <actuator name="right_arm_motor_2">
      <hardwareInterface>hardware_interface/PositionJointInterface</hardwareInterface>
      <mechanicalReduction>1</mechanicalReduction>
    </actuator>
  </transmission>
  <transmission name="right_arm_tran_3">
    <type>transmission_interface/SimpleTransmission</type>
    <joint name="right_arm_joint3">
      <hardwareInterface>hardware_interface/PositionJointInterface</hardwareInterface>
    </joint>
    <actuator name="right_arm_motor_3">
      <hardwareInterface>hardware_interface/PositionJointInterface</hardwareInterface>
      <mechanicalReduction>1</mechanicalReduction>
    </actuator>
  </transmission>
  <transmission name="right_arm_tran_4">
    <type>transmission_interface/SimpleTransmission</type>
    <joint name="right_arm_joint4">
      <hardwareInterface>hardware_interface/PositionJointInterface</hardwareInterface>
    </joint>
    <actuator name="right_arm_motor_4">
      <hardwareInterface>hardware_interface/PositionJointInterface</hardwareInterface>
      <mechanicalReduction>1</mechanicalReduction>
    </actuator>
  </transmission>
  <transmission name="right_arm_tran_5">
    <type>transmission_interface/SimpleTransmission</type>
    <joint name="right_arm_joint5">
      <hardwareInterface>hardware_interface/PositionJointInterface</hardwareInterface>
    </joint>
    <actuator name="right_arm_motor_5">
      <hardwareInterface>hardware_interface/PositionJointInterface</hardwareInterface>
      <mechanicalReduction>1</mechanicalReduction>
    </actuator>
  </transmission>
  <transmission name="right_arm_tran_6">
    <type>transmission_interface/SimpleTransmission</type>
    <joint name="right_arm_joint6">
      <hardwareInterface>hardware_interface/PositionJointInterface</hardwareInterface>
    </joint>
    <actuator name="right_arm_motor_6">
      <hardwareInterface>hardware_interface/PositionJointInterface</hardwareInterface>
      <mechanicalReduction>1</mechanicalReduction>
    </actuator>
  </transmission>
  <transmission name="right_arm_tran_7">
    <type>transmission_interface/SimpleTransmission</type>
    <joint name="right_arm_joint7">
      <hardwareInterface>hardware_interface/PositionJointInterface</hardwareInterface>
    </joint>
    <actuator name="right_arm_motor_7">
      <hardwareInterface>hardware_interface/PositionJointInterface</hardwareInterface>
      <mechanicalReduction>1</mechanicalReduction>
    </actuator>
  </transmission>
  <link name="left_camera_base">
    <visual>
      <geometry>
        <box size="0.04 0.18 0.047"/>
      </geometry>
      <!--geometry>
          <mesh filename="package://aescape_gazebo/meshes/visual/kinect.dae"/>
        </geometry-->
    </visual>
    <collision>
      <geometry>
        <box size="0.04 0.18 0.047"/>
      </geometry>
    </collision>
    <inertial>
      <mass value="0.2"/>
      <inertia ixx="1.0" ixy="0.0" ixz="0.0" iyy="1.0" iyz="0.0" izz="1.0"/>
    </inertial>
  </link>
  <joint name="joint_left_camera_base_camera_to_left_arm_base_link" type="fixed">
    <parent link="left_arm_base_link"/>
    <child link="left_camera_base"/>
    <origin rpy="2.610 1.156 -0.605" xyz="0.1404396785274887 -0.05307111179809734 1.358923271686402"/>
  </joint>
  <gazebo reference="left_camera_base">
    <sensor name="left_camera_base" type="depth">
      <update_rate>10</update_rate>
      <camera>
        <horizontal_fov>1.047198</horizontal_fov>
        <image>
          <width>640</width>
          <height>480</height>
          <format>R8G8B8</format>
        </image>
        <clip>
          <near>0.05</near>
          <far>3</far>
        </clip>
      </camera>
      <plugin filename="libgazebo_ros_openni_kinect.so" name="camera_controller">
        <baseline>0.2</baseline>
        <alwaysOn>true</alwaysOn>
        <updateRate>1.0</updateRate>
        <cameraName>left_camera_base_camera_ir</cameraName>
        <imageTopicName>/left_camera_base/camera/color/image_raw</imageTopicName>
        <cameraInfoTopicName>/left_camera_base/camera/color/camera_info</cameraInfoTopicName>
        <depthImageTopicName>/left_camera_base/camera/depth/image_raw</depthImageTopicName>
        <depthImageInfoTopicName>/left_camera_base/camera/depth/camera_info</depthImageInfoTopicName>
        <pointCloudTopicName>/left_camera_base/camera/depth/points</pointCloudTopicName>
        <frameName>left_camera_base</frameName>
        <pointCloudCutoff>0.5</pointCloudCutoff>
        <pointCloudCutoffMax>3.0</pointCloudCutoffMax>
        <distortionK1>0.00000001</distortionK1>
        <distortionK2>0.00000001</distortionK2>
        <distortionK3>0.00000001</distortionK3>
        <distortionT1>0.00000001</distortionT1>
        <distortionT2>0.00000001</distortionT2>
        <CxPrime>0</CxPrime>
        <Cx>0</Cx>
        <Cy>0</Cy>
        <focalLength>0</focalLength>
        <hackBaseline>0</hackBaseline>
      </plugin>
    </sensor>
  </gazebo>
  <link name="center_camera_base">
    <visual>
      <geometry>
        <box size="0.04 0.18 0.047"/>
      </geometry>
      <!--geometry>
          <mesh filename="package://aescape_gazebo/meshes/visual/kinect.dae"/>
        </geometry-->
    </visual>
    <collision>
      <geometry>
        <box size="0.04 0.18 0.047"/>
      </geometry>
    </collision>
    <inertial>
      <mass value="0.2"/>
      <inertia ixx="1.0" ixy="0.0" ixz="0.0" iyy="1.0" iyz="0.0" izz="1.0"/>
    </inertial>
  </link>
  <joint name="joint_center_camera_base_camera_to_left_arm_base_link" type="fixed">
    <parent link="left_arm_base_link"/>
    <child link="center_camera_base"/>
    <origin rpy="1.482 0.767 -1.520" xyz="0.512 0.885 1.288"/>
  </joint>
  <gazebo reference="center_camera_base">
    <sensor name="center_camera_base" type="depth">
      <update_rate>10</update_rate>
      <camera>
        <horizontal_fov>1.047198</horizontal_fov>
        <image>
          <width>640</width>
          <height>480</height>
          <format>R8G8B8</format>
        </image>
        <clip>
          <near>0.05</near>
          <far>3</far>
        </clip>
      </camera>
      <plugin filename="libgazebo_ros_openni_kinect.so" name="camera_controller">
        <baseline>0.2</baseline>
        <alwaysOn>true</alwaysOn>
        <updateRate>1.0</updateRate>
        <cameraName>center_camera_base_camera_ir</cameraName>
        <imageTopicName>/center_camera_base/camera/color/image_raw</imageTopicName>
        <cameraInfoTopicName>/center_camera_base/camera/color/camera_info</cameraInfoTopicName>
        <depthImageTopicName>/center_camera_base/camera/depth/image_raw</depthImageTopicName>
        <depthImageInfoTopicName>/center_camera_base/camera/depth/camera_info</depthImageInfoTopicName>
        <pointCloudTopicName>/center_camera_base/camera/depth/points</pointCloudTopicName>
        <frameName>center_camera_base</frameName>
        <pointCloudCutoff>0.5</pointCloudCutoff>
        <pointCloudCutoffMax>3.0</pointCloudCutoffMax>
        <distortionK1>0.00000001</distortionK1>
        <distortionK2>0.00000001</distortionK2>
        <distortionK3>0.00000001</distortionK3>
        <distortionT1>0.00000001</distortionT1>
        <distortionT2>0.00000001</distortionT2>
        <CxPrime>0</CxPrime>
        <Cx>0</Cx>
        <Cy>0</Cy>
        <focalLength>0</focalLength>
        <hackBaseline>0</hackBaseline>
      </plugin>
    </sensor>
  </gazebo>
  <link name="right_camera_base">
    <visual>
      <geometry>
        <box size="0.04 0.18 0.047"/>
      </geometry>
      <!--geometry>
          <mesh filename="package://aescape_gazebo/meshes/visual/kinect.dae"/>
        </geometry-->
    </visual>
    <collision>
      <geometry>
        <box size="0.04 0.18 0.047"/>
      </geometry>
    </collision>
    <inertial>
      <mass value="0.2"/>
      <inertia ixx="1.0" ixy="0.0" ixz="0.0" iyy="1.0" iyz="0.0" izz="1.0"/>
    </inertial>
  </link>
  <joint name="joint_right_camera_base_camera_to_left_arm_base_link" type="fixed">
    <parent link="left_arm_base_link"/>
    <child link="right_camera_base"/>
    <origin rpy="-2.960 1.106 -2.920" xyz="0.890 -0.033 1.358"/>
  </joint>
  <gazebo reference="right_camera_base">
    <sensor name="right_camera_base" type="depth">
      <update_rate>10</update_rate>
      <camera>
        <horizontal_fov>1.047198</horizontal_fov>
        <image>
          <width>640</width>
          <height>480</height>
          <format>R8G8B8</format>
        </image>
        <clip>
          <near>0.05</near>
          <far>3</far>
        </clip>
      </camera>
      <plugin filename="libgazebo_ros_openni_kinect.so" name="camera_controller">
        <baseline>0.2</baseline>
        <alwaysOn>true</alwaysOn>
        <updateRate>1.0</updateRate>
        <cameraName>right_camera_base_camera_ir</cameraName>
        <imageTopicName>/right_camera_base/camera/color/image_raw</imageTopicName>
        <cameraInfoTopicName>/right_camera_base/camera/color/camera_info</cameraInfoTopicName>
        <depthImageTopicName>/right_camera_base/camera/depth/image_raw</depthImageTopicName>
        <depthImageInfoTopicName>/right_camera_base/camera/depth/camera_info</depthImageInfoTopicName>
        <pointCloudTopicName>/right_camera_base/camera/depth/points</pointCloudTopicName>
        <frameName>right_camera_base</frameName>
        <pointCloudCutoff>0.5</pointCloudCutoff>
        <pointCloudCutoffMax>3.0</pointCloudCutoffMax>
        <distortionK1>0.00000001</distortionK1>
        <distortionK2>0.00000001</distortionK2>
        <distortionK3>0.00000001</distortionK3>
        <distortionT1>0.00000001</distortionT1>
        <distortionT2>0.00000001</distortionT2>
        <CxPrime>0</CxPrime>
        <Cx>0</Cx>
        <Cy>0</Cy>
        <focalLength>0</focalLength>
        <hackBaseline>0</hackBaseline>
      </plugin>
    </sensor>
  </gazebo>
  <link name="table_center">
    <visual>
      <geometry>
        <box size="0.76 1.83 0.1"/>
      </geometry>
      <!--material name="Grey">
	      <color rgba="0.5 0.5 0.5 0.8"/>
      </material-->
      <origin rpy="0 0 0" xyz="0 -0.6332 -0.05"/>
    </visual>
    <collision>
      <geometry>
        <box size="0.76 1.83 0.1"/>
      </geometry>
      <origin rpy="0 0 0" xyz="0 -0.6332 -0.05"/>
    </collision>
    <inertial>
      <mass value="0.2"/>
      <inertia ixx="1.0" ixy="0.0" ixz="0.0" iyy="1.0" iyz="0.0" izz="1.0"/>
    </inertial>
    <gazebo reference="table_center">
      <material>Gazebo/Black</material>
      <mu1>0.2</mu1>
      <mu2>0.2</mu2>
    </gazebo>
  </link>
  <joint name="table_center_calibration" type="fixed">
    <parent link="left_arm_base_link"/>
    <child link="table_center"/>
    <origin rpy="0 0 0" xyz="0.5058 -0.023642 0.3334"/>
    <!-- Default Values -->
  </joint>
  <!-- <link name="table">
    <visual>
      <geometry>
	<mesh filename="package://aescape_description/meshes/BaseFrame_Collada.dae"/>
      </geometry>
    </visual>
    <collision>
      <geometry>
	<mesh filename="package://aescape_description/meshes/BaseFrame_Collada.dae"/>
      </geometry>
    </collision>
  </link>
  <joint name="table_base_joint" type="fixed">
    <origin xyz="0 -0.25 -0.305" rpy="0 0 0"/>
    <parent link="table_center"/>
    <child link="table"/>
  </joint> -->
  <link name="canonical_body_origin"/>
  <joint name="canonical_body_joint" type="fixed">
    <origin rpy="0 0 0" xyz="0 0.0468 0"/>
    <parent link="table_center"/>
    <child link="canonical_body_origin"/>
  </joint>
  <link name="canonical_smpl_origin"/>
  <joint name="canonical_smpl_origin_joint" type="fixed">
    <origin rpy="0 3.14 0" xyz="0 0 0.1"/>
    <parent link="table_center"/>
    <child link="canonical_smpl_origin"/>
  </joint>
</robot>

